<?xml version="1.0" ?>
<!-- =================================================================================== -->
<!-- |    This document was autogenerated by xacro from debra.xacro                    | -->
<!-- |    EDITING THIS FILE BY HAND IS NOT RECOMMENDED                                 | -->
<!-- =================================================================================== -->
<robot name="debra" xmlns:controller="http://playerstage.sourceforge.net/gazebo/xmlschema/#controller" xmlns:interface="http://playerstage.sourceforge.net/gazebo/xmlschema/#interface" xmlns:sensor="http://playerstage.sourceforge.net/gazebo/xmlschema/#sensor" xmlns:xacro="http://www.ros.org/wiki/xacro">
  <!-- in kg-->
  <!-- in kg -->
  <material name="Black">
    <color rgba="0.0 0.0 0.0 1.0"/>
  </material>
  <material name="Blue">
    <color rgba="0.0 0.0 0.8 1.0"/>
  </material>
  <material name="Green">
    <color rgba="0.0 0.8 0.0 1.0"/>
  </material>
  <material name="LightLightGrey">
    <color rgba="0.9 0.9 0.9 1.0"/>
  </material>
  <material name="LightGrey">
    <color rgba="0.7 0.7 0.7 1.0"/>
  </material>
  <material name="Grey">
    <color rgba="0.5 0.5 0.5 1.0"/>
  </material>
  <material name="DarkGrey">
    <color rgba="0.3 0.3 0.3 1.0"/>
  </material>
  <material name="DarkDarkGrey">
    <color rgba="0.1 0.1 0.1 1.0"/>
  </material>
  <material name="Orange">
    <color rgba="1.0 0.423529411765 0.0392156862745 1.0"/>
  </material>
  <material name="Brown">
    <color rgba="0.870588235294 0.811764705882 0.764705882353 1.0"/>
  </material>
  <material name="Red">
    <color rgba="0.8 0.0 0.0 1.0"/>
  </material>
  <material name="White">
    <color rgba="1.0 1.0 1.0 1.0"/>
  </material>
  <material name="Yellow">
    <color rgba="0.8 0.8 0.0 1.0"/>
  </material>
  <!-- in kg-->
  <!-- in kg -->
  <!-- BASE-FOOTPRINT -->
  <!-- base_footprint is a fictitious link(frame) that is on the ground right below base_link origin -->
  <link name="base_footprint">
    <visual>
      <origin rpy="0 0 0" xyz="0 0 0"/>
      <geometry>
        <box size="0.001 0.001 0.001"/>
      </geometry>
    </visual>
  </link>
  <gazebo reference="base_footprint">
    <turnGravityOff>false</turnGravityOff>
  </gazebo>
  <joint name="base_footprint_joint" type="fixed">
    <origin rpy="0 0 0" xyz="0 0 0.015"/>
    <parent link="base_footprint"/>
    <child link="base_link"/>
    <hardwareInterface>EffortJointInterface</hardwareInterface>
  </joint>
  <!-- BASE-LINK -->
  <!--Actual body/chassis of the robot-->
  <link name="base_link">
    <visual>
      <origin rpy="0 0 1.57079632679" xyz="0 0 0"/>
      <geometry>
        <mesh filename="package://debra_description/meshes/base_link.stl"/>
      </geometry>
      <material name="White"/>
    </visual>
    <collision>
      <origin rpy="0 0 1.57079632679" xyz="0 0 0"/>
      <geometry>
        <mesh filename="package://debra_description/meshes/base_link.stl"/>
      </geometry>
    </collision>
    <inertial>
      <origin rpy="0 0 1.57079632679" xyz="0 0 0"/>
      <mass value="0.546"/>
      <inertia ixx="0.1" ixy="0.0" ixz="0.0" iyy="0.1" iyz="0.0" izz="0.1"/>
    </inertial>
  </link>
  <gazebo reference="base_link">
    <mu1>0.2</mu1>
    <mu2>0.2</mu2>
    <material>Gazebo/White</material>
    <turnGravityOff>false</turnGravityOff>
  </gazebo>
  <!--lr: left, right -->
  <link name="base_link_right_wheel">
    <visual>
      <origin rpy="0 -3.14159265359 1.57079632679" xyz="0 0 0"/>
      <geometry>
        <mesh filename="package://debra_description/meshes/wheel.stl"/>
      </geometry>
      <material name="Yellow"/>
    </visual>
    <collision>
      <origin rpy="0 -3.14159265359 1.57079632679" xyz="0 0 0"/>
      <geometry>
        <mesh filename="package://debra_description/meshes/wheel.stl"/>
      </geometry>
    </collision>
    <inertial>
      <origin rpy="0 -3.14159265359 1.57079632679" xyz="0 0 0"/>
      <mass value="0.066"/>
      <inertia ixx="0.1" ixy="0.0" ixz="0.0" iyy="0.1" iyz="0.0" izz="0.1"/>
    </inertial>
  </link>
  <gazebo reference="base_link_right_wheel">
    <mu1 value="1.0"/>
    <mu2 value="1.0"/>
    <kp value="0.0"/>
    <kd value="0.0"/>
    <fdir1 value="1 0 0"/>
    <material>Gazebo/Yellow</material>
    <turnGravityOff>false</turnGravityOff>
  </gazebo>
  <joint name="base_link_right_wheel_joint" type="continuous">
    <parent link="base_link"/>
    <child link="base_link_right_wheel"/>
    <hardwareInterface>EffortJointInterface</hardwareInterface>
    <origin rpy="0 0 0" xyz="-0.005                    -0.078                    0.015"/>
    <axis rpy="0 0 0" xyz="0 1 0"/>
    <limit effort="10" velocity="2"/>
    <joint_properties damping="0.0" friction="0.0"/>
  </joint>
  <!-- Transmission is important to link the joints and the controller -->
  <transmission name="base_link_right_wheel_joint_trans">
    <type>transmission_interface/SimpleTransmission</type>
    <joint name="base_link_right_wheel_joint">
      <hardwareInterface>EffortJointInterface</hardwareInterface>
    </joint>
    <actuator name="base_link_right_wheel_joint_motor">
      <hardwareInterface>EffortJointInterface</hardwareInterface>
      <mechanicalReduction>1</mechanicalReduction>
    </actuator>
  </transmission>
  <!--lr: left, right -->
  <link name="base_link_left_wheel">
    <visual>
      <origin rpy="0 0.0 1.57079632679" xyz="0 0 0"/>
      <geometry>
        <mesh filename="package://debra_description/meshes/wheel.stl"/>
      </geometry>
      <material name="Yellow"/>
    </visual>
    <collision>
      <origin rpy="0 0.0 1.57079632679" xyz="0 0 0"/>
      <geometry>
        <mesh filename="package://debra_description/meshes/wheel.stl"/>
      </geometry>
    </collision>
    <inertial>
      <origin rpy="0 0.0 1.57079632679" xyz="0 0 0"/>
      <mass value="0.066"/>
      <inertia ixx="0.1" ixy="0.0" ixz="0.0" iyy="0.1" iyz="0.0" izz="0.1"/>
    </inertial>
  </link>
  <gazebo reference="base_link_left_wheel">
    <mu1 value="1.0"/>
    <mu2 value="1.0"/>
    <kp value="0.0"/>
    <kd value="0.0"/>
    <fdir1 value="1 0 0"/>
    <material>Gazebo/Yellow</material>
    <turnGravityOff>false</turnGravityOff>
  </gazebo>
  <joint name="base_link_left_wheel_joint" type="continuous">
    <parent link="base_link"/>
    <child link="base_link_left_wheel"/>
    <hardwareInterface>EffortJointInterface</hardwareInterface>
    <origin rpy="0 0 0" xyz="-0.005                    0.078                    0.015"/>
    <axis rpy="0 0 0" xyz="0 1 0"/>
    <limit effort="10" velocity="2"/>
    <joint_properties damping="0.0" friction="0.0"/>
  </joint>
  <!-- Transmission is important to link the joints and the controller -->
  <transmission name="base_link_left_wheel_joint_trans">
    <type>transmission_interface/SimpleTransmission</type>
    <joint name="base_link_left_wheel_joint">
      <hardwareInterface>EffortJointInterface</hardwareInterface>
    </joint>
    <actuator name="base_link_left_wheel_joint_motor">
      <hardwareInterface>EffortJointInterface</hardwareInterface>
      <mechanicalReduction>1</mechanicalReduction>
    </actuator>
  </transmission>
  <!-- z_offset: distance between base plate and laser center (= center of mesh) -->
  <joint name="base_link_laser_joint" type="fixed">
    <parent link="base_link"/>
    <child link="laser"/>
    <origin rpy="0 0 0" xyz="0 0 0.06296"/>
  </joint>
  <link name="laser">
    <visual>
      <geometry>
        <mesh filename="package://sick_tim/meshes/sick_tim551.stl"/>
      </geometry>
      <material name="blue">
        <color rgba="0 0 1 1"/>
      </material>
    </visual>
    <collision>
      <geometry>
        <mesh filename="package://sick_tim/meshes/sick_tim551.stl"/>
      </geometry>
    </collision>
    <inertial>
      <mass value="0.25"/>
      <origin xyz="0 0 -0.026"/>
      <inertia ixx="0.01548332714" ixy="0.0" ixz="0.0" iyy="0.01548332714" iyz="0.0" izz="0.00014999994"/>
    </inertial>
  </link>
  <gazebo reference="laser">
    <material value="Gazebo/Blue"/>
    <sensor name="laser" type="ray">
      <always_on>true</always_on>
      <update_rate>15.0</update_rate>
      <pose>0 0 0 0 0 0</pose>
      <visualize>true</visualize>
      <ray>
        <scan>
          <horizontal>
            <samples>813</samples>
            <resolution>0.33</resolution>
            <min_angle>-2.357</min_angle>
            <max_angle>2.357</max_angle>
          </horizontal>
        </scan>
        <range>
          <min>0.05</min>
          <max>10.0</max>
          <resolution>0.01</resolution>
        </range>
      </ray>
      <plugin filename="libgazebo_ros_laser.so" name="gazebo_ros_laser_controller">
        <gaussianNoise>0.005</gaussianNoise>
        <alwaysOn>true</alwaysOn>
        <updateRate>15.0</updateRate>
        <topicName>scan</topicName>
        <frameName>laser</frameName>
      </plugin>
    </sensor>
  </gazebo>
</robot>

