<?xml version="1.0"?>
<robot name="wheel" xmlns:xacro="http://www.ros.org/wiki/xacro">

  <!-- Included URDF/XACRO Files -->
  <xacro:include
    filename="$(find debra_description)/urdf/common_properties.xacro" />

  <!-- Wheels -->
  <xacro:macro name="wheel"
               params="lr parent translateX translateY flipY">
  <!--lr: left, right -->
    <link name="${parent}_${lr}_wheel">
      <visual>
        <origin xyz="0 0 0"
                rpy="0 ${(flipY - 1) * M_PI / 2} ${M_PI / 2}" />
        <geometry>
          <mesh filename="package://debra_description/meshes/wheel.stl" />
        </geometry>
        <material name="wheel_color">
          <color rgba="0.867 0.910 1 1" />
        </material>
      </visual>
      <collision>
        <origin xyz="0 0 0"
                rpy="0 ${(flipY - 1) * M_PI / 2} ${M_PI / 2}" />
        <geometry>
          <mesh filename="package://debra_description/meshes/wheel.stl" />
        </geometry>
      </collision>
       <inertial>
        <origin xyz="0 0 0"
                rpy="0 ${(flipY - 1) * M_PI / 2} ${M_PI / 2}" />
        <mass value="0.066" />
        <inertia ixx="1.234E-05" ixy="-4.969E-22" ixz="-1.613E-23"
                 iyy="4.849E-22" iyz="-6.502E-06"
                 izz="3.112E-22" />
      </inertial>
    </link>

    <gazebo reference="${parent}_${lr}_wheel">
      <mu1 value="1.0"/>
      <mu2 value="1.0"/>
      <kp  value="10000000.0" />
      <kd  value="1.0" />
      <fdir1 value="1 0 0"/>
      <material>Gazebo/Blue</material>
      <turnGravityOff>false</turnGravityOff>
    </gazebo>

    <joint name="${parent}_${lr}_wheel_joint"
           type="continuous">
      <parent link="${parent}"/>
      <child link="${parent}_${lr}_wheel"/>
      <hardwareInterface>EffortJointInterface</hardwareInterface>
      <origin xyz="${translateX * base_x_origin_to_wheel_origin}
                   ${translateY * base_y_origin_to_wheel_origin}
                   ${base_z_origin_to_wheel_origin}"
              rpy="0 0 0" />
      <axis xyz="0 1 0"
            rpy="0 0 0" />
      <limit effort="100"
             velocity="100"/>
      <joint_properties damping="0.0"
                        friction="0.0"/>
    </joint>

    <!-- Transmission is important to link the joints and the controller -->
    <transmission name="${parent}_${lr}_wheel_joint_trans">
      <type>transmission_interface/SimpleTransmission</type>
      <joint name="${parent}_${lr}_wheel_joint">
        <hardwareInterface>EffortJointInterface</hardwareInterface>
      </joint>
      <actuator name="${parent}_${lr}_wheel_joint_motor">
        <hardwareInterface>EffortJointInterface</hardwareInterface>
        <mechanicalReduction>1</mechanicalReduction>
      </actuator>
    </transmission>

  </xacro:macro>
</robot>
