<?xml version="1.0"?>
<robot name="wheel" xmlns:xacro="http://www.ros.org/wiki/xacro">

  <!-- Included URDF/XACRO Files -->
  <xacro:include
    filename="$(find debra_description)/urdf/common_properties.xacro" />

  <!-- Wheels -->
  <xacro:macro name="wheel"
               params="lr parent translateX translateY flipY">
  <!--lr: left, right -->
    <link name="${parent}_${lr}_wheel">
      <visual>
        <origin xyz="0 0 0"
                rpy="${flipY * M_PI / 2} 0 0" />
        <geometry>
          <cylinder length="${wheel_height}"
                    radius="${wheel_radius}" />
        </geometry>
        <material name="DarkGrey" />
      </visual>
      <collision>
        <origin xyz="0 0 0"
                rpy="${flipY * M_PI / 2} 0 0" />
        <geometry>
          <cylinder length="${wheel_height}" radius="${wheel_radius}" />
        </geometry>
      </collision>
      <inertial>
        <mass value="${wheel_mass}" />
        <origin xyz="0 0 0"
                rpy="0 0 0" />
        <cylinder_inertia  m="${wheel_mass}"
                           r="${wheel_radius}"
                           h="${wheel_height}" />
      </inertial>
    </link>

    <gazebo reference="${parent}_${lr}_wheel">
      <mu1 value="1.0"/>
      <mu2 value="1.0"/>
      <kp  value="10000000.0" />
      <kd  value="1.0" />
      <fdir1 value="1 0 0"/>
      <material>Gazebo/Blue</material>
      <turnGravityOff>false</turnGravityOff>
    </gazebo>

    <joint name="${parent}_${lr}_wheel_joint"
           type="continuous">
      <parent link="${parent}"/>
      <child link="${parent}_${lr}_wheel"/>
      <hardwareInterface>EffortJointInterface</hardwareInterface>
      <origin xyz="${translateX * base_x_origin_to_wheel_origin}
                   ${translateY * base_y_origin_to_wheel_origin}
                   ${base_z_origin_to_wheel_origin}"
              rpy="0 0 0" />
      <axis xyz="0 1 0"
            rpy="0 0 0" />
      <limit effort="100"
             velocity="100"/>
      <joint_properties damping="0.0"
                        friction="0.0"/>
    </joint>

    <!-- Transmission is important to link the joints and the controller -->
    <transmission name="${parent}_${lr}_wheel_joint_trans">
      <type>transmission_interface/SimpleTransmission</type>
      <joint name="${parent}_${lr}_wheel_joint" />
      <actuator name="${parent}_${lr}_wheel_joint_motor">
        <hardwareInterface>EffortJointInterface</hardwareInterface>
        <mechanicalReduction>1</mechanicalReduction>
      </actuator>
    </transmission>

  </xacro:macro>
</robot>
